<?xml version="1.0"?>
<robot name="ar601" xmlns:xacro="http://www.ros.org/wiki/xacro">
    <xacro:macro name="cube" params="name">

        <link name="${name}_flange">
            <inertial>
                <mass value="0.02"/>
                <origin xyz="0.0 0.0 0.033" rpy="0 0 0"/>
                <inertia ixx="0.0015" ixy="0.0" ixz="0.0"
                         iyy="0.001" iyz="0.0"
                         izz="0.001"/>
            </inertial>
            <collision name="${name}_flange_collision">
                <origin xyz="0.0 0.0 0.033" rpy="0 0 0"/>
                <geometry>
                    <mesh filename="package://qbmove_example/meshes/c_flange.dae"/>
                </geometry>
            </collision>
            <visual name="${name}_flange_visual">
                <origin xyz="0.0 0 0.05" rpy="-1.57 0 3.14"/>
                <geometry>
                    <mesh filename="package://qbmove_example/meshes/c_flange.dae"/>
                </geometry>
            </visual>
        </link>
        <gazebo reference="${name}_flange">
            <material>Gazebo/Blue</material>
        </gazebo>

        <joint name="${name}_joint" type="revolute">
            <parent link="${name}_cube"/>
            <child link="${name}_flange"/>
            <origin xyz="0 0 0" rpy="0 0 0"/>
            <axis xyz="1 0 0"/>
            <limit lower="-1.5" upper="1.5" effort="200" velocity="3"/>
        </joint>

        <link name="${name}_cube">
            <inertial>
                <mass value="1"/>
                <origin xyz="0 0 0.03" rpy="0 0 0"/>
                <inertia ixx="0.015625" ixy="0.0" ixz="0.0"
                         iyy="0.015625" iyz="0.0"
                         izz="0.015625"/>
            </inertial>
            <collision name="${name}_cube_collision">
                <origin xyz="0.0 0.0 0.033" rpy="0 0 0"/>
                <geometry>
                    <mesh filename="package://qbmove_example/meshes/cube.dae"/>
                </geometry>
            </collision>
            <visual name="${name}_cube_visual">
                <origin xyz="0.0 0 0.0" rpy="0.0 1.57 0"/>
                <geometry>
                    <mesh filename="package://qbmove_example/meshes/cube.dae"/>
                </geometry>
            </visual>
        </link>
        <gazebo reference="${name}_cube">
            <material>Gazebo/Grey</material>
        </gazebo>

        <joint name="${name}_motor1_joint" type="revolute">
            <parent link="${name}_cube"/>
            <child link="${name}_motor1"/>
            <origin xyz="0.016 -0.007 -0.002" rpy="0 0 0"/>
            <axis xyz="1 0 0"/>
            <limit lower="-1.5" upper="1.5" effort="200" velocity="3"/>
        </joint>

        <link name="${name}_motor1">
            <inertial>
                <mass value="0.001"/>
                <origin xyz="0.016 -0.007 -0.002" rpy="0 95.0 0"/>
                <inertia ixx="0.01" ixy="0.0" ixz="0.0"
                         iyy="0.01" iyz="0.0"
                         izz="0.01"/>
            </inertial>
        </link>
        <joint name="${name}_motor2_joint" type="revolute">
            <parent link="${name}_cube"/>
            <child link="${name}_motor2"/>
            <origin xyz="0.012 0.008 0.01" rpy="0 0 0"/>
            <axis xyz="1 0 0"/>
            <limit lower="-1.5" upper="1.5" effort="200" velocity="3"/>
        </joint>

        <link name="${name}_motor2">
            <inertial>
                <mass value="0.001"/>
                <origin xyz="0.012 0.008 0.01" rpy="0 95.0 0"/>
                <inertia ixx="0.01" ixy="0.0" ixz="0.0"
                         iyy="0.01" iyz="0.0"
                         izz="0.01"/>
            </inertial>
        </link>

    </xacro:macro>
</robot>
